Workbook
Name ___________GIP100: [1]library!$D$218
Name __________GIP100: [1]library!$D$218
Name _________GIP100: [1]library!$D$218
Name ________GIP100: [1]library!$D$218
Name ________zl152: #REF!
Name ________zl152: #REF!
Name _______GIP100: [1]library!$D$218
Name ______GIP100: [1]library!$D$218
Name _____GIP100: [1]library!$D$218
Name ____GIP100: [1]library!$D$218
Name ____HPC8: #REF!
Name ____HPC8: #REF!
Name ____TAR20: #REF!
Name ____TAR20: #REF!
Name ___GIP100: [1]library!$D$218
Name ___HPC8: #REF!
Name ___HPC8: #REF!
Name ___TAR20: #REF!
Name ___TAR20: #REF!
Name __123Graph_B: '[2]CProy laba rugi'!#REF!
Name __123Graph_B: '[3]CProy laba rugi'!#REF!
Name __123Graph_X: '[4]CProy laba rugi'!#REF!
Name __123Graph_X: '[5]CProy laba rugi'!#REF!
Name __FDS_HYPERLINK_TOGGLE_STATE__: "ON"
Name __GIP100: [1]library!$D$218
Name __HPC8: #REF!
Name __HPC8: #REF!
Name __TAR20: #REF!
Name __TAR20: #REF!
Name _1Excel_BuiltIn_Print_Area_2: #REF!
Name _1Excel_BuiltIn_Print_Area_2: #REF!
Name _2Excel_BuiltIn_Print_Area_2: #REF!
Name _2Excel_BuiltIn_Print_Area_2: #REF!
Name _4Excel_BuiltIn_Print_Area_2: #REF!
Name _4Excel_BuiltIn_Print_Area_2: #REF!
Name _910A: #REF!
Name _910A: #REF!
Name _91A: #REF!
Name _91A: #REF!
Name _92A: #REF!
Name _92A: #REF!
Name _93A: #REF!
Name _93A: #REF!
Name _94A: #REF!
Name _94A: #REF!
Name _95A: #REF!
Name _95A: #REF!
Name _96A: #REF!
Name _96A: #REF!
Name _97AA: #REF!
Name _97AA: #REF!
Name _98A: #REF!
Name _98A: #REF!
Name _99A: #REF!
Name _99A: #REF!
Name _99B: #REF!
Name _99B: #REF!
Name _GIP100: [1]library!$D$218
Name _HPC8: #REF!
Name _HPC8: #REF!

Sheet GUIDE SHEET
E2: 1. INPUT DATA FROM TECHNICAL
B3: GET DATA FROM TECHNICAL | E3: 2. GET DATA FROM COMMERCIAL & FINANCE | H3: CALCULATIONS | K3: OUTPUT
B9: DEMAND AND PROJECTIONS | H9: OPEX
B11: CAPEX | E11: INPUT DATA & ASSUMPTIONS | H11: DEPRECIATION SCHEDULE | K11: TARIFF CALCULATION
B13: OPEX | H13: AMORTIZATION SCHEDULE
D18: OPEX
D19: DEPRECIATION
D20: AMORTIZATION | H20: BILLED VOLUME | K20: PHP TARIFF / CU.M.
D21: EQUITY
D22: 2- MOS. WORKING CAPITAL

Sheet BOHOL DEMAND PROJECTION
B2: Demand Projection
C4: POPULATION
C5: City/Municipality | D5: WSPs | G5: 2019 | H5: 2020 | I5: 2021 | J5: 2022 | K5: 2023 | L5: 45352 | M5: 2024 | N5: 2025 | O5: 2026 | P5: 2027 | Q5: 2028 | R5: 2029 | S5: 2030 | T5: 2031 | U5: 2032 | V5: 2033 | W5: 2034 | X5: 2035 | Y5: 2036 | Z5: 2037 | AA5: 2038 | AB5: 2039 | AC5: 2040 | AD5: 2041 | AE5: 2042 | AF5: 2043 | AG5: 2044 | AH5: 2045 | AI5: 2046 | AJ5: 2047 | AK5: 2048 | AL5: 2049 | AM5: 2050 | AN5: 2051 | AO5: 2052 | AP5: 2053 | AQ5: 2054 | AR5: 2055
B8: 1 | C8: Alburquerque | D8: LGU-run, BLGU-run | H8: 11246 | I8: 11438.448 | J8: 11634.189 | K8: 11833.279 | L8: 12035.777 | M8: 12035.777 | N8: 12241.74 | O8: 12437.214 | P8: 12635.809 | Q8: 12837.575 | R8: 13042.563 | S8: 13250.825 | T8: 13446.202 | U8: 13644.459 | V8: 13845.64 | W8: 14049.787 | X8: 14256.944 | Y8: 14446.956 | Z8: 14639.5 | AA8: 14834.61 | AB8: 15032.32 | AC8: 15232.665 | AD8: 15418.9 | AE8: 15607.411 | AF8: 15798.226 | AG8: 15991.375 | AH8: 16186.885 | AI8: 16384.785 | AJ8: 16585.105 | AK8: 16787.874 | AL8: 16993.122 | AM8: 17200.88 | AN8: 17411.177 | AO8: 17624.046 | AP8: 17839.517 | AQ8: 18057.622 | AR8: 18278.394
B9: 2 | C9: Baclayon | D9: LGU-run, BWUI, BLGU-run | H9: 22461 | I9: 22845.365 | J9: 23236.307 | K9: 23633.94 | L9: 24038.377 | M9: 24038.377 | N9: 24449.734 | O9: 24840.144 | P9: 25236.787 | Q9: 25639.763 | R9: 26049.175 | S9: 26465.123 | T9: 26855.339 | U9: 27251.307 | V9: 27653.114 | W9: 28060.846 | X9: 28474.589 | Y9: 28854.088 | Z9: 29238.645 | AA9: 29628.327 | AB9: 30023.203 | AC9: 30423.342 | AD9: 30795.296 | AE9: 31171.799 | AF9: 31552.904 | AG9: 31938.669 | AH9: 32329.15 | AI9: 32724.406 | AJ9: 33124.493 | AK9: 33529.472 | AL9: 33939.402 | AM9: 34354.345 | AN9: 34774.36 | AO9: 35199.51 | AP9: 35629.858 | AQ9: 36065.468 | AR9: 36506.403
B10: 3 | C10: Corella | D10: LGU-run | H10: 9479 | I10: 9641.2098 | J10: 9806.1955 | K10: 9974.0045 | L10: 10144.685 | M10: 10144.685 | N10: 10318.286 | O10: 10483.047 | P10: 10650.439 | Q10: 10820.503 | R10: 10993.283 | S10: 11168.822 | T10: 11333.5 | U10: 11500.607 | V10: 11670.178 | W10: 11842.249 | X10: 12016.857 | Y10: 12177.014 | Z10: 12339.304 | AA10: 12503.758 | AB10: 12670.404 | AC10: 12839.271 | AD10: 12996.243 | AE10: 13155.135 | AF10: 13315.969 | AG10: 13478.77 | AH10: 13643.561 | AI10: 13810.366 | AJ10: 13979.212 | AK10: 14150.121 | AL10: 14323.12 | AM10: 14498.234 | AN10: 14675.489 | AO10: 14854.911 | AP10: 15036.527 | AQ10: 15220.363 | AR10: 15406.446
B11: 4 | C11: Dauis | D11: LGU-run, BLGU-run, Richli, Balibago, BWUI (bulk) | H11: 52492 | I11: 53390.272 | J11: 54303.915 | K11: 55233.194 | L11: 56178.374 | M11: 56178.374 | N11: 57139.729 | O11: 58052.127 | P11: 58979.093 | Q11: 59920.861 | R11: 60877.667 | S11: 61849.751 | T11: 62761.695 | U11: 63687.085 | V11: 64626.12 | W11: 65579 | X11: 66545.93 | Y11: 67432.83 | Z11: 68331.551 | AA11: 69242.249 | AB11: 70165.085 | AC11: 71100.22 | AD11: 71969.489 | AE11: 72849.386 | AF11: 73740.041 | AG11: 74641.584 | AH11: 75554.15 | AI11: 76477.873 | AJ11: 77412.889 | AK11: 78359.336 | AL11: 79317.355 | AM11: 80287.087 | AN11: 81268.674 | AO11: 82262.263 | AP11: 83267.999 | AQ11: 84286.031 | AR11: 85316.509
B12: 5 | C12: Loboc | D12: LGU-run, BLGU-run | H12: 17418 | I12: 17716.066 | J12: 18019.233 | K12: 18327.588 | L12: 18641.22 | M12: 18641.22 | N12: 18960.219 | O12: 19262.972 | P12: 19570.56 | Q12: 19883.059 | R12: 20200.549 | S12: 20523.108 | T12: 20825.711 | U12: 21132.776 | V12: 21444.368 | W12: 21760.554 | X12: 22081.403 | Y12: 22375.696 | Z12: 22673.911 | AA12: 22976.101 | AB12: 23282.318 | AC12: 23592.617 | AD12: 23881.059 | AE12: 24173.028 | AF12: 24468.567 | AG12: 24767.719 | AH12: 25070.528 | AI12: 25377.04 | AJ12: 25687.299 | AK12: 26001.351 | AL12: 26319.243 | AM12: 26641.021 | AN12: 26966.733 | AO12: 27296.428 | AP12: 27630.153 | AQ12: 27967.959 | AR12: 28309.894
B13: 6 | C13: Panglao | D13: LGU-run, BLGU-run, Richli, Balibago, Mactan Rock, Abejo | H13: 39839 | I13: 40520.747 | J13: 41214.16 | K13: 41919.439 | L13: 42636.787 | M13: 42636.787 | N13: 43366.411 | O13: 44058.879 | P13: 44762.403 | Q13: 45477.162 | R13: 46203.333 | S13: 46941.1 | T13: 47633.224 | U13: 48335.552 | V13: 49048.236 | W13: 49771.428 | X13: 50505.283 | Y13: 51178.399 | Z13: 51860.487 | AA13: 52551.664 | AB13: 53252.054 | AC13: 53961.778 | AD13: 54621.513 | AE13: 55289.314 | AF13: 55965.28 | AG13: 56649.51 | AH13: 57342.105 | AI13: 58043.168 | AJ13: 58752.802 | AK13: 59471.112 | AL13: 60198.204 | AM13: 60934.185 | AN13: 61679.165 | AO13: 62433.252 | AP13: 63196.559 | AQ13: 63969.199 | AR13: 64751.284
B14: 7 | C14: Sikatuna | D14: LGU-run | H14: 6906 | I14: 7024.1792 | J14: 7144.3808 | K14: 7266.6394 | L14: 7390.9901 | M14: 7390.9901 | N14: 7517.4688 | O14: 7637.5064 | P14: 7759.4608 | Q14: 7883.3625 | R14: 8009.2427 | S14: 8137.1329 | T14: 8257.1109 | U14: 8378.8579 | V14: 8502.4001 | W14: 8627.7638 | X14: 8754.9759 | Y14: 8871.659 | Z14: 8989.8973 | AA14: 9109.7115 | AB14: 9231.1224 | AC14: 9354.1515 | AD14: 9468.5151 | AE14: 9584.2769 | AF14: 9701.4539 | AG14: 9820.0636 | AH14: 9940.1234 | AI14: 10061.651 | AJ14: 10184.665 | AK14: 10309.182 | AL14: 10435.222 | AM14: 10562.802 | AN14: 10691.943 | AO14: 10822.662 | AP14: 10954.98 | AQ14: 11088.915 | AR14: 11224.488
B15: 8 | C15: Tagbilaran City | D15: LGU-run, BWUI, Richli | H15: 104976 | I15: 106772.41 | J15: 108599.55 | K15: 110457.97 | L15: 112348.19 | M15: 112348.19 | N15: 114270.75 | O15: 116095.41 | P15: 117949.2 | Q15: 119832.59 | R15: 121746.06 | S15: 123690.08 | T15: 125513.83 | U15: 127364.46 | V15: 129242.39 | W15: 131148.01 | X15: 133081.72 | Y15: 134855.38 | Z15: 136652.69 | AA15: 138473.95 | AB15: 140319.48 | AC15: 142189.6 | AD15: 143928.01 | AE15: 145687.67 | AF15: 147468.84 | AG15: 149271.79 | AH15: 151096.78 | AI15: 152944.09 | AJ15: 154813.98 | AK15: 156706.73 | AL15: 158622.62 | AM15: 160561.94 | AN15: 162524.96 | AO15: 164511.99 | AP15: 166523.31 | AQ15: 168559.22 | AR15: 170620.02
C16: TOTAL | H16: 264817 | I16: 269348.69 | J16: 273957.94 | K16: 278646.05 | L16: 283414.4 | M16: 283414.4 | N16: 288264.34 | O16: 292867.29 | P16: 297543.75 | Q16: 302294.88 | R16: 307121.87 | S16: 312025.94 | T16: 316626.61 | U16: 321295.11 | V16: 326032.45 | W16: 330839.63 | X16: 335717.7 | Y16: 340192.03 | Z16: 344725.98 | AA16: 349320.37 | AB16: 353975.98 | AC16: 358693.65 | AD16: 363079.03 | AE16: 367518.02 | AF16: 372011.28 | AG16: 376559.48 | AH16: 381163.29 | AI16: 385823.38 | AJ16: 390540.44 | AK16: 395315.18 | AL16: 400148.29 | AM16: 405040.49 | AN16: 409992.5 | AO16: 415005.06 | AP16: 420078.9 | AQ16: 425214.77 | AR16: 430413.43
C18: HOUSEHOLDS
C19: City/Municipality | D19: WSPs | G19: 2019 | H19: 2020 | I19: 2021 | J19: 2022 | K19: 2023 | L19: 45352 | M19: 2024 | N19: 2025 | O19: 2026 | P19: 2027 | Q19: 2028 | R19: 2029 | S19: 2030 | T19: 2031 | U19: 2032 | V19: 2033 | W19: 2034 | X19: 2035 | Y19: 2036 | Z19: 2037 | AA19: 2038 | AB19: 2039 | AC19: 2040 | AD19: 2041 | AE19: 2042 | AF19: 2043 | AG19: 2044 | AH19: 2045 | AI19: 2046 | AJ19: 2047 | AK19: 2048 | AL19: 2049 | AM19: 2050 | AN19: 2051 | AO19: 2052 | AP19: 2053 | AQ19: 2054 | AR19: 2055
B22: 1 | C22: Alburquerque | D22: LGU-run, BLGU-run | H22: 2615.3488 | I22: 2660.1041 | J22: 2705.6253 | K22: 2751.9254 | L22: 2799.0179 | M22: 2799.0179 | N22: 2846.9162 | O22: 2892.3753 | P22: 2938.5602 | Q22: 2985.4826 | R22: 3033.1543 | S22: 3081.5872 | T22: 3127.0237 | U22: 3173.1301 | V22: 3219.9163 | W22: 3267.3924 | X22: 3315.5685 | Y22: 3359.7572 | Z22: 3404.5348 | AA22: 3449.9092 | AB22: 3495.8884 | AC22: 3542.4803 | AD22: 3585.7906 | AE22: 3629.6304 | AF22: 3674.0061 | AG22: 3718.9244 | AH22: 3764.3919 | AI22: 3810.4152 | AJ22: 3857.0012 | AK22: 3904.1568 | AL22: 3951.8889 | AM22: 4000.2046 | AN22: 4049.111 | AO22: 4098.6153 | AP22: 4148.7248 | AQ22: 4199.447 | AR22: 4250.7893
B23: 2 | C23: Baclayon | D23: LGU-run, BWUI, BLGU-run | H23: 5104.7727 | I23: 5192.1284 | J23: 5280.9789 | K23: 5371.3499 | L23: 5463.2674 | M23: 5463.2674 | N23: 5556.7578 | O23: 5645.4872 | P23: 5735.6333 | Q23: 5827.2189 | R23: 5920.267 | S23: 6014.8008 | T23: 6103.486 | U23: 6193.4789 | V23: 6284.7987 | W23: 6377.465 | X23: 6471.4975 | Y23: 6557.7473 | Z23: 6645.1466 | AA23: 6733.7108 | AB23: 6823.4553 | AC23: 6914.3958 | AD23: 6998.931 | AE23: 7084.4997 | AF23: 7171.1146 | AG23: 7258.7884 | AH23: 7347.5342 | AI23: 7437.3649 | AJ23: 7528.2939 | AK23: 7620.3346 | AL23: 7713.5006 | AM23: 7807.8056 | AN23: 7903.2636 | AO23: 7999.8886 | AP23: 8097.695 | AQ23: 8196.6972 | AR23: 8296.9098
B24: 3 | C24: Corella | D24: LGU-run | H24: 2204.4186 | I24: 2242.1418 | J24: 2280.5106 | K24: 2319.5359 | L24: 2359.2291 | M24: 2359.2291 | N24: 2399.6015 | O24: 2437.9179 | P24: 2476.8462 | Q24: 2516.396 | R24: 2556.5774 | S24: 2597.4004 | T24: 2635.6978 | U24: 2674.5599 | V24: 2713.9949 | W24: 2754.0114 | X24: 2794.618 | Y24: 2831.8636 | Z24: 2869.6057 | AA24: 2907.8508 | AB24: 2946.6056 | AC24: 2985.8769 | AD24: 3022.3821 | AE24: 3059.3337 | AF24: 3096.737 | AG24: 3134.5976 | AH24: 3172.9211 | AI24: 3211.7131 | AJ24: 3250.9794 | AK24: 3290.7258 | AL24: 3330.9581 | AM24: 3371.6823 | AN24: 3412.9044 | AO24: 3454.6305 | AP24: 3496.8667 | AQ24: 3539.6193 | AR24: 3582.8945
B25: 4 | C25: Dauis | D25: LGU-run, BLGU-run, Richli, Balibago, BWUI (bulk) | H25: 11411.304 | I25: 11606.581 | J25: 11805.199 | K25: 12007.216 | L25: 12212.69 | M25: 12212.69 | N25: 12421.68 | O25: 12620.028 | P25: 12821.542 | Q25: 13026.274 | R25: 13234.275 | S25: 13445.598 | T25: 13643.847 | U25: 13845.019 | V25: 14049.157 | W25: 14256.304 | X25: 14466.507 | Y25: 14659.311 | Z25: 14854.685 | AA25: 15052.663 | AB25: 15253.279 | AC25: 15456.57 | AD25: 15645.541 | AE25: 15836.823 | AF25: 16030.444 | AG25: 16226.431 | AH25: 16424.815 | AI25: 16625.624 | AJ25: 16828.889 | AK25: 17034.638 | AL25: 17242.903 | AM25: 17453.715 | AN25: 17667.103 | AO25: 17883.101 | AP25: 18101.739 | AQ25: 18323.05 | AR25: 18547.067
B26: 5 | C26: Loboc | D26: LGU-run, BLGU-run | H26: 3958.6364 | I26: 4026.3787 | J26: 4095.2803 | K26: 4165.361 | L26: 4236.6409 | M26: 4236.6409 | N26: 4309.1406 | O26: 4377.9482 | P26: 4447.8546 | Q26: 4518.8771 | R26: 4591.0338 | S26: 4664.3426 | T26: 4733.1161 | U26: 4802.9035 | V26: 4873.72 | W26: 4945.5806 | X26: 5018.5007 | Y26: 5085.3855 | Z26: 5153.1617 | AA26: 5221.8412 | AB26: 5291.436 | AC26: 5361.9583 | AD26: 5427.5135 | AE26: 5493.8701 | AF26: 5561.038 | AG26: 5629.0271 | AH26: 5697.8474 | AI26: 5767.5091 | AJ26: 5838.0225 | AK26: 5909.398 | AL26: 5981.6461 | AM26: 6054.7775 | AN26: 6128.803 | AO26: 6203.7336 | AP26: 6279.5803 | AQ26: 6356.3542 | AR26: 6434.0668
B27: 6 | C27: Panglao | D27: LGU-run, BLGU-run, Richli, Balibago, Mactan Rock, Abejo | H27: 8660.6522 | I27: 8808.858 | J27: 8959.6 | K27: 9112.9215 | L27: 9268.8668 | M27: 9268.8668 | N27: 9427.4808 | O27: 9578.0171 | P27: 9730.9573 | Q27: 9886.3395 | R27: 10044.203 | S27: 10204.587 | T27: 10355.049 | U27: 10507.729 | V27: 10662.66 | W27: 10819.876 | X27: 10979.409 | Y27: 11125.739 | Z27: 11274.019 | AA27: 11424.275 | AB27: 11576.534 | AC27: 11730.821 | AD27: 11874.242 | AE27: 12019.416 | AF27: 12166.365 | AG27: 12315.111 | AH27: 12465.675 | AI27: 12618.08 | AJ27: 12772.348 | AK27: 12928.503 | AL27: 13086.566 | AM27: 13246.562 | AN27: 13408.514 | AO27: 13572.446 | AP27: 13738.382 | AQ27: 13906.348 | AR27: 14076.366
B28: 7 | C28: Sikatuna | D28: LGU-run | H28: 1726.5 | I28: 1756.0448 | J28: 1786.0952 | K28: 1816.6598 | L28: 1847.7475 | M28: 1847.7475 | N28: 1879.3672 | O28: 1909.3766 | P28: 1939.8652 | Q28: 1970.8406 | R28: 2002.3107 | S28: 2034.2832 | T28: 2064.2777 | U28: 2094.7145 | V28: 2125.6 | W28: 2156.9409 | X28: 2188.744 | Y28: 2217.9148 | Z28: 2247.4743 | AA28: 2277.4279 | AB28: 2307.7806 | AC28: 2338.5379 | AD28: 2367.1288 | AE28: 2396.0692 | AF28: 2425.3635 | AG28: 2455.0159 | AH28: 2485.0309 | AI28: 2515.4128 | AJ28: 2546.1661 | AK28: 2577.2955 | AL28: 2608.8054 | AM28: 2640.7006 | AN28: 2672.9857 | AO28: 2705.6656 | AP28: 2738.7449 | AQ28: 2772.2288 | AR28: 2806.1219
B29: 8 | C29: Tagbilaran City | D29: LGU-run, BWUI, Richli | H29: 23328 | I29: 23727.201 | J29: 24133.234 | K29: 24546.215 | L29: 24966.264 | M29: 24966.264 | N29: 25393.5 | O29: 25798.979 | P29: 26210.933 | Q29: 26629.464 | R29: 27054.679 | S29: 27486.684 | T29: 27891.961 | U29: 28303.214 | V29: 28720.531 | W29: 29144.001 | X29: 29573.715 | Y29: 29967.863 | Z29: 30367.264 | AA29: 30771.988 | AB29: 31182.106 | AC29: 31597.69 | AD29: 31984.002 | AE29: 32375.038 | AF29: 32770.854 | AG29: 33171.509 | AH29: 33577.063 | AI29: 33987.575 | AJ29: 34403.107 | AK29: 34823.718 | AL29: 35249.472 | AM29: 35680.431 | AN29: 36116.658 | AO29: 36558.22 | AP29: 37005.179 | AQ29: 37457.603 | AR29: 37915.559
C30: TOTAL | H30: 59009.633 | I30: 60019.438 | J30: 61046.524 | K30: 62091.185 | L30: 63153.723 | M30: 63153.723 | N30: 64234.444 | O30: 65260.129 | P30: 66302.191 | Q30: 67360.893 | R30: 68436.501 | S30: 69529.283 | T30: 70554.458 | U30: 71594.748 | V30: 72650.378 | W30: 73721.572 | X30: 74808.56 | Y30: 75805.581 | Z30: 76815.891 | AA30: 77839.666 | AB30: 78877.085 | AC30: 79928.33 | AD30: 80905.531 | AE30: 81894.68 | AF30: 82895.922 | AG30: 83909.405 | AH30: 84935.279 | AI30: 85973.695 | AJ30: 87024.807 | AK30: 88088.769 | AL30: 89165.74 | AM30: 90255.878 | AN30: 91359.343 | AO30: 92476.3 | AP30: 93606.912 | AQ30: 94751.348 | AR30: 95909.775
C32: HOUSEHOLD SIZE
C33: City/Municipality | D33: WSPs | G33: 2019 | H33: 2020 | I33: 2021 | J33: 2022 | K33: 2023 | L33: 45352 | M33: 2024 | N33: 2025 | O33: 2026 | P33: 2027 | Q33: 2028 | R33: 2029 | S33: 2030 | T33: 2031 | U33: 2032 | V33: 2033 | W33: 2034 | X33: 2035 | Y33: 2036 | Z33: 2037 | AA33: 2038 | AB33: 2039 | AC33: 2040 | AD33: 2041 | AE33: 2042 | AF33: 2043 | AG33: 2044 | AH33: 2045 | AI33: 2046 | AJ33: 2047 | AK33: 2048 | AL33: 2049 | AM33: 2050 | AN33: 2051 | AO33: 2052 | AP33: 2053 | AQ33: 2054 | AR33: 2055
B36: 1 | C36: Alburquerque | D36: LGU-run, BLGU-run | G36: 4.3 | H36: 4.3 | I36: 4.3 | J36: 4.3 | K36: 4.3 | L36: 4.3 | M36: 4.3 | N36: 4.3 | O36: 4.3 | P36: 4.3 | Q36: 4.3 | R36: 4.3 | S36: 4.3 | T36: 4.3 | U36: 4.3 | V36: 4.3 | W36: 4.3 | X36: 4.3 | Y36: 4.3 | Z36: 4.3 | AA36: 4.3 | AB36: 4.3 | AC36: 4.3 | AD36: 4.3 | AE36: 4.3 | AF36: 4.3 | AG36: 4.3 | AH36: 4.3 | AI36: 4.3 | AJ36: 4.3 | AK36: 4.3 | AL36: 4.3 | AM36: 4.3 | AN36: 4.3 | AO36: 4.3 | AP36: 4.3 | AQ36: 4.3 | AR36: 4.3
B37: 2 | C37: Baclayon | D37: LGU-run, BWUI, BLGU-run | G37: 4.4 | H37: 4.4 | I37: 4.4 | J37: 4.4 | K37: 4.4 | L37: 4.4 | M37: 4.4 | N37: 4.4 | O37: 4.4 | P37: 4.4 | Q37: 4.4 | R37: 4.4 | S37: 4.4 | T37: 4.4 | U37: 4.4 | V37: 4.4 | W37: 4.4 | X37: 4.4 | Y37: 4.4 | Z37: 4.4 | AA37: 4.4 | AB37: 4.4 | AC37: 4.4 | AD37: 4.4 | AE37: 4.4 | AF37: 4.4 | AG37: 4.4 | AH37: 4.4 | AI37: 4.4 | AJ37: 4.4 | AK37: 4.4 | AL37: 4.4 | AM37: 4.4 | AN37: 4.4 | AO37: 4.4 | AP37: 4.4 | AQ37: 4.4 | AR37: 4.4
B38: 3 | C38: Corella | D38: LGU-run | G38: 4.3 | H38: 4.3 | I38: 4.3 | J38: 4.3 | K38: 4.3 | L38: 4.3 | M38: 4.3 | N38: 4.3 | O38: 4.3 | P38: 4.3 | Q38: 4.3 | R38: 4.3 | S38: 4.3 | T38: 4.3 | U38: 4.3 | V38: 4.3 | W38: 4.3 | X38: 4.3 | Y38: 4.3 | Z38: 4.3 | AA38: 4.3 | AB38: 4.3 | AC38: 4.3 | AD38: 4.3 | AE38: 4.3 | AF38: 4.3 | AG38: 4.3 | AH38: 4.3 | AI38: 4.3 | AJ38: 4.3 | AK38: 4.3 | AL38: 4.3 | AM38: 4.3 | AN38: 4.3 | AO38: 4.3 | AP38: 4.3 | AQ38: 4.3 | AR38: 4.3
B39: 4 | C39: Dauis | D39: LGU-run, BLGU-run, Richli, Balibago, BWUI (bulk) | G39: 4.6 | H39: 4.6 | I39: 4.6 | J39: 4.6 | K39: 4.6 | L39: 4.6 | M39: 4.6 | N39: 4.6 | O39: 4.6 | P39: 4.6 | Q39: 4.6 | R39: 4.6 | S39: 4.6 | T39: 4.6 | U39: 4.6 | V39: 4.6 | W39: 4.6 | X39: 4.6 | Y39: 4.6 | Z39: 4.6 | AA39: 4.6 | AB39: 4.6 | AC39: 4.6 | AD39: 4.6 | AE39: 4.6 | AF39: 4.6 | AG39: 4.6 | AH39: 4.6 | AI39: 4.6 | AJ39: 4.6 | AK39: 4.6 | AL39: 4.6 | AM39: 4.6 | AN39: 4.6 | AO39: 4.6 | AP39: 4.6 | AQ39: 4.6 | AR39: 4.6
B40: 5 | C40: Loboc | D40: LGU-run, BLGU-run | G40: 4.4 | H40: 4.4 | I40: 4.4 | J40: 4.4 | K40: 4.4 | L40: 4.4 | M40: 4.4 | N40: 4.4 | O40: 4.4 | P40: 4.4 | Q40: 4.4 | R40: 4.4 | S40: 4.4 | T40: 4.4 | U40: 4.4 | V40: 4.4 | W40: 4.4 | X40: 4.4 | Y40: 4.4 | Z40: 4.4 | AA40: 4.4 | AB40: 4.4 | AC40: 4.4 | AD40: 4.4 | AE40: 4.4 | AF40: 4.4 | AG40: 4.4 | AH40: 4.4 | AI40: 4.4 | AJ40: 4.4 | AK40: 4.4 | AL40: 4.4 | AM40: 4.4 | AN40: 4.4 | AO40: 4.4 | AP40: 4.4 | AQ40: 4.4 | AR40: 4.4
B41: 6 | C41: Panglao | D41: LGU-run, BLGU-run, Richli, Balibago, Mactan Rock, Abejo | G41: 4.6 | H41: 4.6 | I41: 4.6 | J41: 4.6 | K41: 4.6 | L41: 4.6 | M41: 4.6 | N41: 4.6 | O41: 4.6 | P41: 4.6 | Q41: 4.6 | R41: 4.6 | S41: 4.6 | T41: 4.6 | U41: 4.6 | V41: 4.6 | W41: 4.6 | X41: 4.6 | Y41: 4.6 | Z41: 4.6 | AA41: 4.6 | AB41: 4.6 | AC41: 4.6 | AD41: 4.6 | AE41: 4.6 | AF41: 4.6 | AG41: 4.6 | AH41: 4.6 | AI41: 4.6 | AJ41: 4.6 | AK41: 4.6 | AL41: 4.6 | AM41: 4.6 | AN41: 4.6 | AO41: 4.6 | AP41: 4.6 | AQ41: 4.6 | AR41: 4.6
B42: 7 | C42: Sikatuna | D42: LGU-run | G42: 4 | H42: 4 | I42: 4 | J42: 4 | K42: 4 | L42: 4 | M42: 4 | N42: 4 | O42: 4 | P42: 4 | Q42: 4 | R42: 4 | S42: 4 | T42: 4 | U42: 4 | V42: 4 | W42: 4 | X42: 4 | Y42: 4 | Z42: 4 | AA42: 4 | AB42: 4 | AC42: 4 | AD42: 4 | AE42: 4 | AF42: 4 | AG42: 4 | AH42: 4 | AI42: 4 | AJ42: 4 | AK42: 4 | AL42: 4 | AM42: 4 | AN42: 4 | AO42: 4 | AP42: 4 | AQ42: 4 | AR42: 4
B43: 8 | C43: Tagbilaran City | D43: LGU-run, BWUI, Richli | G43: 4.5 | H43: 4.5 | I43: 4.5 | J43: 4.5 | K43: 4.5 | L43: 4.5 | M43: 4.5 | N43: 4.5 | O43: 4.5 | P43: 4.5 | Q43: 4.5 | R43: 4.5 | S43: 4.5 | T43: 4.5 | U43: 4.5 | V43: 4.5 | W43: 4.5 | X43: 4.5 | Y43: 4.5 | Z43: 4.5 | AA43: 4.5 | AB43: 4.5 | AC43: 4.5 | AD43: 4.5 | AE43: 4.5 | AF43: 4.5 | AG43: 4.5 | AH43: 4.5 | AI43: 4.5 | AJ43: 4.5 | AK43: 4.5 | AL43: 4.5 | AM43: 4.5 | AN43: 4.5 | AO43: 4.5 | AP43: 4.5 | AQ43: 4.5 | AR43: 4.5
L44: 4.487691 | M44: 4.487691 | N44: 4.487691 | O44: 4.487691 | P44: 4.487691 | Q44: 4.487691 | R44: 4.487691 | S44: 4.487691 | T44: 4.487691 | U44: 4.487691 | V44: 4.487691 | W44: 4.487691 | X44: 4.487691 | Y44: 4.487691 | Z44: 4.487691 | AA44: 4.487691 | AB44: 4.487691 | AC44: 4.487691 | AD44: 4.487691 | AE44: 4.487691 | AF44: 4.487691 | AG44: 4.487691 | AH44: 4.487691 | AI44: 4.487691 | AJ44: 4.487691 | AK44: 4.487691 | AL44: 4.487691 | AM44: 4.487691 | AN44: 4.487691 | AO44: 4.487691 | AP44: 4.487691 | AQ44: 4.487691 | AR44: 4.487691
C46: HOUSEHOLD COVERAGE (%) - served by all
C47: City/Municipality | D47: WSPs | G47: 2019 | H47: 2020 | I47: 2021 | J47: 2022 | K47: 2023 | L47: 45352 | M47: 2024 | N47: 2025 | O47: 2026 | P47: 2027 | Q47: 2028 | R47: 2029 | S47: 2030 | T47: 2031 | U47: 2032 | V47: 2033 | W47: 2034 | X47: 2035 | Y47: 2036 | Z47: 2037 | AA47: 2038 | AB47: 2039 | AC47: 2040 | AD47: 2041 | AE47: 2042 | AF47: 2043 | AG47: 2044 | AH47: 2045 | AI47: 2046 | AJ47: 2047 | AK47: 2048 | AL47: 2049 | AM47: 2050 | AN47: 2051 | AO47: 2052 | AP47: 2053 | AQ47: 2054 | AR47: 2055
K48: based on WSC of LGU waterworks | L48: based on WSC of LGU waterworks | M48: based on WSC of LGU waterworks | N48: assumed saturation of brgys served by the waterworks
B50: 1 | C50: Alburquerque | D50: LGU-run, BLGU-run | K50: 0.73766534 | L50: 0.74025966 | M50: 0.74766225 | N50: 1 | O50: 1 | P50: 1 | Q50: 1 | R50: 1 | S50: 1 | T50: 1 | U50: 1 | V50: 1 | W50: 1 | X50: 1 | Y50: 1 | Z50: 1 | AA50: 1 | AB50: 1 | AC50: 1 | AD50: 1 | AE50: 1 | AF50: 1 | AG50: 1 | AH50: 1 | AI50: 1 | AJ50: 1 | AK50: 1 | AL50: 1 | AM50: 1 | AN50: 1 | AO50: 1 | AP50: 1 | AQ50: 1 | AR50: 1
B51: 2 | C51: Baclayon | D51: LGU-run, BWUI, BLGU-run | K51: 0.71229766 | L51: 0.70031352 | M51: 0.70031352 | N51: 1 | O51: 1 | P51: 1 | Q51: 1 | R51: 1 | S51: 1 | T51: 1 | U51: 1 | V51: 1 | W51: 1 | X51: 1 | Y51: 1 | Z51: 1 | AA51: 1 | AB51: 1 | AC51: 1 | AD51: 1 | AE51: 1 | AF51: 1 | AG51: 1 | AH51: 1 | AI51: 1 | AJ51: 1 | AK51: 1 | AL51: 1 | AM51: 1 | AN51: 1 | AO51: 1 | AP51: 1 | AQ51: 1 | AR51: 1
B52: 3 | C52: Corella | D52: LGU-run | K52: 0.97864404 | L52: 0.96217871 | M52: 0.96217871 | N52: 1.082497 | O52: 1.0820124 | P52: 1.0815307 | Q52: 1.0810518 | R52: 1.0805757 | S52: 1.0801024 | T52: 1.0797279 | U52: 1.0793551 | V52: 1.0789841 | W52: 1.0786148 | X52: 1.0782472 | Y52: 1.0779902 | Z52: 1.0777341 | AA52: 1.0774789 | AB52: 1.0772244 | AC52: 1.0769708 | AD52: 1.0768016 | AE52: 1.0766327 | AF52: 1.0764641 | AG52: 1.076296 | AH52: 1.0761282 | AI52: 1.0759608 | AJ52: 1.0757938 | AK52: 1.0756271 | AL52: 1.0754608 | AM52: 1.0752948 | AN52: 1.0751292 | AO52: 1.074964 | AP52: 1.0747992 | AQ52: 1.0746347 | AR52: 1.0744706
...

Sheet Tagbilaran CAPEX&OPEX_realistic
B1: CAPEX
D2: Year 1 | E2: Year 2 | F2: Year 3 | G2: Year 4 | H2: Year 5 | I2: Year 6 | J2: Year 7 | K2: Year 8 | L2: Year 9 | M2: Year 10 | N2: Year 11 | O2: Year 12 | P2: Year 13 | Q2: Year 14 | R2: Year 15 | S2: Year 16 | T2: Year 17 | U2: Year 18 | V2: Year 19 | W2: Year 20 | X2: Year 21 | Y2: Year 22 | Z2: Year 23 | AA2: Year 24 | AB2: Year 25 | AC2: Year 26 | AD2: Year 27 | AE2: Year 28 | AF2: Year 29 | AG2: Year 30
B3: WATER SECURITY | D3: =SUM(D4:D12) -> 0 | E3: =SUM(E4:E12) -> 0 | F3: =SUM(F4:F12) -> 4411400 | G3: =SUM(G4:G12) -> 6617100 | H3: =SUM(H4:H12) -> 0 | I3: =SUM(I4:I12) -> 0 | J3: =SUM(J4:J12) -> 0 | K3: =SUM(K4:K12) -> 0 | ... AG3: =SUM(AG4:AG12) -> 0
B4: 1 | C4: Water Source Development
B5: 2 | C5: WTP and Facilities
B6: 3 | C6: ROW and Land Acquisition
B7: 4 | C7: Pump/Booster Stations
B8: 4.1 | C8: New Booster Stations | F8: ='[42]CAPEX dist Tagbilaran'!$G$29*0.4 -> 4411400 | G8: ='[42]CAPEX dist Tagbilaran'!$G$29*0.6 -> 6617100
B9: 4.2 | C9: New Pump Stations
B10: 5 | C10: New Well Development
B11: 6 | C11: Existing Wells Rehab Works
B12: 6.1 | C12: Well upkeep as reliability units (7 biggest well sources) | M12: =28*0.25*600000 -> 4200000
B13: SERVICE ACCESSIBILITY | D13: =SUM(D14:D51) -> 54332974 | E13: =SUM(E14:E51) -> 93140136 | F13: =SUM(F14:F51) -> 78341057 | G13: =SUM(G14:G51) -> 56634342 | H13: =SUM(H14:H51) -> 0 | I13: =SUM(I14:I51) -> 0 | J13: =SUM(J14:J51) -> 0 | K13: =SUM(K14:K51) -> 0 | ... AG13: =SUM(AG14:AG51) -> 0
B14: 1 | C14: New Lines
B15: 1.1 | C15: 400mm Main Line from Offtake | G15: ='[43]CAPEX dist Tagbilaran'!O42-6000000 -> 22267879 | M15: 6000000
B16: 1.2 | C16: 300mm Main Transmission line | F16: ='[43]CAPEX dist Tagbilaran'!$O$43*0.4-3000000 -> 11516745 | G16: ='[43]CAPEX dist Tagbilaran'!$O$43*0.6-6000000 -> 15775118 | M16: 9000000
B17: 1.3 | C17: 250mm Main Transmission Line | E17: ='[42]CAPEX dist Tagbilaran'!$G$44*0.3 -> 16294412 | F17: ='[42]CAPEX dist Tagbilaran'!$G$44*0.5-9000000 -> 18157353 | G17: ='[42]CAPEX dist Tagbilaran'!$G$44*0.2 -> 10862941 | M17: 9000000
B18: 1.4 | C18: 200mm Main distribution lines and mainline extensions | E18: ='[42]CAPEX dist Tagbilaran'!$G$45*0.4 -> 9817404.4 | F18: ='[42]CAPEX dist Tagbilaran'!$G$45*0.6 -> 14726107
B19: 2 | C19: Pipe Replacements/Reinforcements
B20: 2.1 | C20: 150mm distribution lines | E20: ='[42]CAPEX dist Tagbilaran'!$G$46 -> 7353388.2
B21: Target Areas | C21: Tiptip
C22: Manga
C23: Ubujan
B24: 2.2 | C24: 100mm distribution lines | D24: ='[42]CAPEX dist Tagbilaran'!$G$47*0.3 -> 14887327 | E24: ='[42]CAPEX dist Tagbilaran'!$G$47*0.4 -> 19849769 | F24: ='[42]CAPEX dist Tagbilaran'!$G$47*0.3 -> 14887327
C25: Tiptip
C26: Manga
C27: Ubujan
B28: 2.3 | C28: 75mm distribution lines | D28: ='[43]CAPEX dist Tagbilaran'!$H$48*0.4*0.7 -> 2817651.1 | E28: ='[43]CAPEX dist Tagbilaran'!$H$48*0.6*0.7 -> 4226476.6
C29: Tiptip
C30: Manga
C31: Ubujan
B32: 2.4 | C32: 50mm distribution lines | D32: ='[43]CAPEX dist Tagbilaran'!$H$49*0.3*0.6 -> 8962391.8 | E32: ='[43]CAPEX dist Tagbilaran'!$H$49*0.3*0.6 -> 8962391.8 | F32: ='[43]CAPEX dist Tagbilaran'!$H$49*0.3*0.6 -> 8962391.8 | G32: ='[43]CAPEX dist Tagbilaran'!$H$49*0.1*0.6 -> 2987463.9
C33: Tiptip
C34: Manga
C35: Ubujan
B36: 2.5 | C36: Pipe appurtenances | D36: =SUM('[43]CAPEX dist Tagbilaran'!$H$50:$H$51)/4 -> 1382390 | E36: =SUM('[43]CAPEX dist Tagbilaran'!$H$50:$H$51)/4 -> 1382390 | F36: =SUM('[43]CAPEX dist Tagbilaran'!$H$50:$H$51)/4 -> 1382390 | G36: =SUM('[43]CAPEX dist Tagbilaran'!$H$50:$H$51)/4 -> 1382390
B37: 2.6 | C37: Restoration works | D37: =SUM('[43]CAPEX dist Tagbilaran'!$H$52)*0.3 -> 4100721.6 | E37: =SUM('[43]CAPEX dist Tagbilaran'!$H$52)*0.4 -> 5467628.8 | F37: =SUM('[43]CAPEX dist Tagbilaran'!$H$52)*0.2 -> 2733814.4 | G37: =SUM('[43]CAPEX dist Tagbilaran'!$H$52)*0.1 -> 1366907.2
B38: 3 | C38: Expansion of Coverage
B39: 3.1 | C39: 75mm distribution lines | D39: ='[43]CAPEX dist Tagbilaran'!$H$48*0.4*0.3 -> 1207564.7 | E39: ='[43]CAPEX dist Tagbilaran'!$H$48*0.6*0.3 -> 1811347.1
C40: Cabawan
...

Sheet INPUT DATA  Assumptions
A1: TAGBILARAN CITY RURAL WATERWORKS
A2: ASSUMPTIONS
A3: SUPPLY AND DEMAND | B3: unit | C3: Construction Period (2026-2029) | D3: YR 1 (2030) | E3: YR 2 (2031) | F3: YR3 (2032) | G3: YR 4 (2033) | H3: YR 5 (2034) | I3: YR 6 (2035) | J3: YR 7 (2036) | K3: YR 8 (2037) | L3: YR 9 (2038) | M3: YR 10 (2039)
A4: Service Connections | B4: No. | D4: 10493 | E4: 10648 | F4: 10806 | G4: 10966 | H4: 11128 | I4: 11292 | J4: 11443 | K4: 11596 | L4: 11751 | M4: 11908
A5: DW, m3 | B5: m3 / yr | D5: 0 | E5: 0 | F5: 0 | G5: 0 | H5: 0 | I5: 0 | J5: 0 | K5: 0 | L5: 0 | M5: 0
A6: PWSP, m3 | B6: m3 / yr | D6: 8557477.5 | E6: 8621012.6 | F6: 8741461.2 | G6: 8865025.4 | H6: 8991863.3 | I6: 9122144.8 | J6: 9246266.7 | K6: 9373936.7 | L6: 9505360.8 | M6: 9640761.1
A7: BBWSP, m3 | B7: m3 / yr | D7: 6689710.4 | E7: 5685015.9 | F7: 5753992.5 | G7: 5824193.7 | H7: 5895652.2 | I7: 5967804.3 | J7: 6035096.4 | K7: 6103550.6 | L7: 6173202.1 | M7: 6244088.3
A9: CAPEX | B9: UNIT | C9: Construction Period (2026-2029) | D9: YR 1 (2030) | E9: YR 2 (2031) | F9: YR3 (2032) | G9: YR 4 (2033) | H9: YR 5 (2034) | I9: YR 6 (2035) | J9: YR 7 (2036) | K9: YR 8 (2037) | L9: YR 9 (2038) | M9: YR 10 (2039)
A10: Water Supply System | B10: Php | C10: ='Tagbilaran CAPEX&OPEX_realistic'!D70+'Tagbilaran CAPEX&OPEX_realistic'!E70+'Tagbilaran CAPEX&OPEX_realistic'!F70+'Tagbilaran CAPEX&OPEX_realistic'!G70 -> 5.792428e+08 | D10: ='Tagbilaran CAPEX&OPEX_realistic'!H70 -> 0 | E10: ='Tagbilaran CAPEX&OPEX_realistic'!I70 -> 0 | F10: ='Tagbilaran CAPEX&OPEX_realistic'!J70 -> 0 | G10: ='Tagbilaran CAPEX&OPEX_realistic'!K70 -> 0 | H10: ='Tagbilaran CAPEX&OPEX_realistic'!L70 -> 0 | I10: ='Tagbilaran CAPEX&OPEX_realistic'!M70 -> 1.1405686e+08 | J10: ='Tagbilaran CAPEX&OPEX_realistic'!N70 -> 0 | K10: ='Tagbilaran CAPEX&OPEX_realistic'!O70 -> 0 | ... M10: ='Tagbilaran CAPEX&OPEX_realistic'!Q70 -> 0
A11: Sanitation | B11: Php | D11: 0 | E11: 0 | F11: 0 | G11: 0 | H11: 0 | I11: 0 | J11: 0 | K11: 0 | L11: 0 | M11: 0
A13: OPEX (Water Supply System) | B13: UNIT | C13: Construction Period (2026-2029) | D13: YR 1 (2030) | E13: YR 2 (2031) | F13: YR3 (2032) | G13: YR 4 (2033) | H13: YR 5 (2034) | I13: YR 6 (2035) | J13: YR 7 (2036) | K13: YR 8 (2037) | L13: YR 9 (2038) | M13: YR 10 (2039)
A15: Inflation | B15: 0.05
A16: Staff (1:1000) - (No.) | B16: 250 | D16: =D4/$B$16 -> 41.972 | E16: =E4/$B$16 -> 42.592 | F16: =F4/$B$16 -> 43.224 | G16: =G4/$B$16 -> 43.864 | H16: =H4/$B$16 -> 44.512 | I16: =I4/$B$16 -> 45.168 | J16: =J4/$B$16 -> 45.772 | K16: =K4/$B$16 -> 46.384 | ... M16: =M4/$B$16 -> 47.632
A17: Average Salary per month - (Php) | B17: 19090 | D17: =B17 -> 19090 | E17: =D17*(1+$B$15) -> 20044.5 | F17: =E17*(1+$B$15) -> 21046.725 | G17: =F17*(1+$B$15) -> 22099.061 | H17: =G17*(1+$B$15) -> 23204.014 | I17: =H17*(1+$B$15) -> 24364.215 | J17: =I17*(1+$B$15) -> 25582.426 | K17: =J17*(1+$B$15) -> 26861.547 | L17: =K17*(1+$B$15) -> 28204.624 | M17: =L17*(1+$B$15) -> 29614.856
A18: Power cost / m3 produced - (Php) | B18: 13.13 | D18: =B18 -> 13.13 | E18: =D18*(1+$B$15) -> 13.7865 | F18: =E18*(1+$B$15) -> 14.475825 | G18: =F18*(1+$B$15) -> 15.199616 | H18: =G18*(1+$B$15) -> 15.959597 | I18: =H18*(1+$B$15) -> 16.757577 | J18: =I18*(1+$B$15) -> 17.595456 | K18: =J18*(1+$B$15) -> 18.475229 | L18: =K18*(1+$B$15) -> 19.39899 | M18: =L18*(1+$B$15) -> 20.368939
A19: Chemical Cost / m3 produced | B19: 0.5 | D19: =B19 -> 0.5 | E19: =D19*(1+$B$15) -> 0.525 | F19: =E19*(1+$B$15) -> 0.55125 | G19: =F19*(1+$B$15) -> 0.5788125 | H19: =G19*(1+$B$15) -> 0.60775313 | I19: =H19*(1+$B$15) -> 0.63814078 | J19: =I19*(1+$B$15) -> 0.67004782 | K19: =J19*(1+$B$15) -> 0.70355021 | L19: =K19*(1+$B$15) -> 0.73872772 | M19: =L19*(1+$B$15) -> 0.77566411
A20: Bulk Purchase (2030-2034) | B20: 19.85 | D20: =B20 -> 19.85 | E20: =D20 -> 19.85 | F20: =E20 -> 19.85 | G20: =F20 -> 19.85 | H20: =G20 -> 19.85
A21: Bulk Purchase (2035-2039) | B21: 25.8 | I21: =B21 -> 25.8 | J21: =I21 -> 25.8 | K21: =J21 -> 25.8 | L21: =K21 -> 25.8 | M21: =L21 -> 25.8
A22: Misc and Other O&M (% OF TOTAL OPEX) | B22: 0.05 | D22: =B22 -> 0.05 | E22: =D22 -> 0.05 | F22: =E22 -> 0.05 | G22: =F22 -> 0.05 | H22: =G22 -> 0.05 | I22: =H22 -> 0.05 | J22: =I22 -> 0.05 | K22: =J22 -> 0.05 | L22: =K22 -> 0.05 | M22: =L22 -> 0.05
A23: Service Fee (% OF TOTAL OPEX) | B23: 0.1 | D23: =B23 -> 0.1 | E23: =D23 -> 0.1 | F23: =E23 -> 0.1 | G23: =F23 -> 0.1 | H23: =G23 -> 0.1 | I23: =H23 -> 0.1 | J23: =I23 -> 0.1 | K23: =J23 -> 0.1 | L23: =K23 -> 0.1 | M23: =L23 -> 0.1
A24: Depreciation - Average Economic Life | B24: 25
A27: OPEX (SANITATION) | B27: UNIT | C27: Construction Period (2026-2029) | D27: YR 1 (2030) | E27: YR 2 (2031) | F27: YR3 (2032) | G27: YR 4 (2033) | H27: YR 5 (2034) | I27: YR 6 (2035) | J27: YR 7 (2036) | K27: YR 8 (2037) | L27: YR 9 (2038) | M27: YR 10 (2039)
A28: Salary (Php) | B28: 15000
A29: Staff (No.) | B29: 5
A30: Power cost / m3 - (Php) | B30: 10
A31: Chemical Cost / m3 - (Php) | B31: 5
A32: Misc and Other O&M | B32: 0.05
A33: Service Fee | B33: 0.1
A34: Depreciation - Average Economic Life | B34: 40
A37: LOAN AMORTIZATION
A38: TENOR: | B38: 1 | I38: 1
A39: Total Project Cost (Php) | B39: 0 | C39: =C10 -> 5.792428e+08 | I39: =I10 -> 1.1405686e+08
A40: Loan (%age) | B40: 0 | C40: =C39*B40 -> 0 | I40: 0
A41: Grant (%age) | B41: =B38-B40-B42 -> 1 | C41: =C39*B41 -> 5.792428e+08 | I41: =I38-I40-I42 -> 1
A42: Equity (%age) | B42: 0 | C42: =C39*B42 -> 0 | I42: 0
A43: Interest Rate | B43: 0.05 | I43: 0.05
A44: Repayment Period | B44: 30 | I44: 30
A46: RETURN ON INVESTMENT
A47: ROI (1-12%) | B47: 0 | I47: 0

Sheet OPEX
A1: OPERATIONAL EXPENDITURE (OPEX) & ANNUAL REQUIRED REVENUE (ARR)
A3: TAGBILARAN | D3: CONSTRCTN PRD | E3: year 1 | F3: year 2 | G3: year 3 | H3: year 4 | I3: year 5 | J3: year 6 | K3: year 7 | L3: year 8 | M3: year 9 | N3: year 10
D4: 2026-2029 | E4: 2030 | F4: =E4+1 -> 2031 | G4: =F4+1 -> 2032 | H4: =G4+1 -> 2033 | I4: =H4+1 -> 2034 | J4: =I4+1 -> 2035 | K4: =J4+1 -> 2036 | L4: =K4+1 -> 2037 | M4: =L4+1 -> 2038 | N4: =M4+1 -> 2039
B5: No. of Service Connection | E5: ='INPUT DATA Assumptions'!D4 -> 10493 | F5: ='INPUT DATA Assumptions'!E4 -> 10648 | G5: ='INPUT DATA Assumptions'!F4 -> 10806 | H5: ='INPUT DATA Assumptions'!G4 -> 10966 | I5: ='INPUT DATA Assumptions'!H4 -> 11128 | J5: ='INPUT DATA Assumptions'!I4 -> 11292 | K5: ='INPUT DATA Assumptions'!J4 -> 11443 | L5: ='INPUT DATA Assumptions'!K4 -> 11596 | ... N5: ='INPUT DATA Assumptions'!M4 -> 11908
B6: DW, m3 | E6: ='INPUT DATA Assumptions'!D5 -> 0 | F6: ='INPUT DATA Assumptions'!E5 -> 0 | G6: ='INPUT DATA Assumptions'!F5 -> 0 | H6: ='INPUT DATA Assumptions'!G5 -> 0 | I6: ='INPUT DATA Assumptions'!H5 -> 0 | J6: ='INPUT DATA Assumptions'!I5 -> 0 | K6: ='INPUT DATA Assumptions'!J5 -> 0 | L6: ='INPUT DATA Assumptions'!K5 -> 0 | ... N6: ='INPUT DATA Assumptions'!M5 -> 0
B7: PWSP, M3 | E7: ='INPUT DATA Assumptions'!D6 -> 8557477.5 | F7: ='INPUT DATA Assumptions'!E6 -> 8621012.6 | G7: ='INPUT DATA Assumptions'!F6 -> 8741461.2 | H7: ='INPUT DATA Assumptions'!G6 -> 8865025.4 | I7: ='INPUT DATA Assumptions'!H6 -> 8991863.3 | J7: ='INPUT DATA Assumptions'!I6 -> 9122144.8 | K7: ='INPUT DATA Assumptions'!J6 -> 9246266.7 | L7: ='INPUT DATA Assumptions'!K6 -> 9373936.7 | ... N7: ='INPUT DATA Assumptions'!M6 -> 9640761.1
B8: BBWSP, M3 | E8: ='INPUT DATA Assumptions'!D7 -> 6689710.4 | F8: ='INPUT DATA Assumptions'!E7 -> 5685015.9 | G8: ='INPUT DATA Assumptions'!F7 -> 5753992.5 | H8: ='INPUT DATA Assumptions'!G7 -> 5824193.7 | I8: ='INPUT DATA Assumptions'!H7 -> 5895652.2 | J8: ='INPUT DATA Assumptions'!I7 -> 5967804.3 | K8: ='INPUT DATA Assumptions'!J7 -> 6035096.4 | L8: ='INPUT DATA Assumptions'!K7 -> 6103550.6 | ... N8: ='INPUT DATA Assumptions'!M7 -> 6244088.3
A10: SALARIES | E10: =E11*E12*E13 -> 10416191 | F10: =F11*F12*F13 -> 11098559 | G10: =G11*G12*G13 -> 11826407 | H10: =H11*H12*H13 -> 12601592 | I10: =I11*I12*I13 -> 13427142 | J10: =J11*J12*J13 -> 14306277 | K10: =K11*K12*K13 -> 15222464 | L10: =L11*L12*L13 -> 16197298 | ... N10: =N11*N12*N13 -> 18337992
B11: Number of manpower | E11: ='INPUT DATA Assumptions'!D16 -> 41.972 | F11: ='INPUT DATA Assumptions'!E16 -> 42.592 | G11: ='INPUT DATA Assumptions'!F16 -> 43.224 | H11: ='INPUT DATA Assumptions'!G16 -> 43.864 | I11: ='INPUT DATA Assumptions'!H16 -> 44.512 | J11: ='INPUT DATA Assumptions'!I16 -> 45.168 | K11: ='INPUT DATA Assumptions'!J16 -> 45.772 | L11: ='INPUT DATA Assumptions'!K16 -> 46.384 | ... N11: ='INPUT DATA Assumptions'!M16 -> 47.632
B12: Average Salary | E12: ='INPUT DATA Assumptions'!D17 -> 19090 | F12: ='INPUT DATA Assumptions'!E17 -> 20044.5 | G12: ='INPUT DATA Assumptions'!F17 -> 21046.725 | H12: ='INPUT DATA Assumptions'!G17 -> 22099.061 | I12: ='INPUT DATA Assumptions'!H17 -> 23204.014 | J12: ='INPUT DATA Assumptions'!I17 -> 24364.215 | K12: ='INPUT DATA Assumptions'!J17 -> 25582.426 | L12: ='INPUT DATA Assumptions'!K17 -> 26861.547 | ... N12: ='INPUT DATA Assumptions'!M17 -> 29614.856
B13: 13 months | E13: 13 | F13: 13 | G13: 13 | H13: 13 | I13: 13 | J13: 13 | K13: 13 | L13: 13 | M13: 13 | N13: 13
A15: POWER Cost (Booster)+PWSP | E15: =E16*E17 -> 87835897 | F15: =F16*F17 -> 78376471 | G15: =G16*G17 -> 83293789 | H15: =H16*H17 -> 88525509 | I15: =I16*I17 -> 94092234 | J15: =J16*J17 -> 1.0000594e+08 | K15: =K16*K17 -> 1.0619027e+08 | L15: =L16*L17 -> 1.1276449e+08 | ... N15: =N16*N17 -> 1.2718546e+08
B16: Production in m3 | E16: =E8 -> 6689710.4 | F16: =F8 -> 5685015.9 | G16: =G8 -> 5753992.5 | H16: =H8 -> 5824193.7 | I16: =I8 -> 5895652.2 | J16: =J8 -> 5967804.3 | K16: =K8 -> 6035096.4 | L16: =L8 -> 6103550.6 | ... N16: =N8 -> 6244088.3
B17: Unit cost Php/M3 | E17: ='INPUT DATA Assumptions'!D18 -> 13.13 | F17: ='INPUT DATA Assumptions'!E18 -> 13.7865 | G17: ='INPUT DATA Assumptions'!F18 -> 14.475825 | H17: ='INPUT DATA Assumptions'!G18 -> 15.199616 | I17: ='INPUT DATA Assumptions'!H18 -> 15.959597 | J17: ='INPUT DATA Assumptions'!I18 -> 16.757577 | K17: ='INPUT DATA Assumptions'!J18 -> 17.595456 | L17: ='INPUT DATA Assumptions'!K18 -> 18.475229 | ... N17: ='INPUT DATA Assumptions'!M18 -> 20.368939
A19: CHEMICAL Cost | E19: =E20*E21 -> 0 | F19: =F20*F21 -> 0 | G19: =G20*G21 -> 0 | H19: =H20*H21 -> 0 | I19: =I20*I21 -> 0 | J19: =J20*J21 -> 0 | K19: =K20*K21 -> 0 | L19: =L20*L21 -> 0 | ... N19: =N20*N21 -> 0
B20: Production in m3 | D20: 0 | E20: =E6 -> 0 | F20: =F6 -> 0 | G20: =G6 -> 0 | H20: =H6 -> 0 | I20: =I6 -> 0 | J20: =J6 -> 0 | K20: =K6 -> 0 | L20: =L6 -> 0 | ... N20: =N6 -> 0
B21: Unit Cost Php/m3 | E21: ='INPUT DATA Assumptions'!D19 -> 0.5 | F21: ='INPUT DATA Assumptions'!E19 -> 0.525 | G21: ='INPUT DATA Assumptions'!F19 -> 0.55125 | H21: ='INPUT DATA Assumptions'!G19 -> 0.5788125 | I21: ='INPUT DATA Assumptions'!H19 -> 0.60775313 | J21: ='INPUT DATA Assumptions'!I19 -> 0.63814078 | K21: ='INPUT DATA Assumptions'!J19 -> 0.67004782 | L21: ='INPUT DATA Assumptions'!K19 -> 0.70355021 | ... N21: ='INPUT DATA Assumptions'!M19 -> 0.77566411
A23: BULK WATER PURCHASE | E23: =E24*E25 -> 1.3279075e+08 | F23: =F24*F25 -> 1.1284757e+08 | G23: =G24*G25 -> 1.1421675e+08 | H23: =H24*H25 -> 1.1561025e+08 | I23: =I24*I25 -> 1.170287e+08 | J23: =J24*J25 -> 1.5396935e+08 | K23: =K24*K25 -> 1.5570549e+08 | L23: =L24*L25 -> 1.574716e+08 | ... N23: =N24*N25 -> 1.6109748e+08
B24: BBWPS | D24: 0 | E24: =E8 -> 6689710.4 | F24: =F8 -> 5685015.9 | G24: =G8 -> 5753992.5 | H24: =H8 -> 5824193.7 | I24: =I8 -> 5895652.2 | J24: =J8 -> 5967804.3 | K24: =K8 -> 6035096.4 | L24: =L8 -> 6103550.6 | ... N24: =N8 -> 6244088.3
B25: Bulk Rate | E25: ='INPUT DATA Assumptions'!D20 -> 19.85 | F25: ='INPUT DATA Assumptions'!E20 -> 19.85 | G25: ='INPUT DATA Assumptions'!F20 -> 19.85 | H25: ='INPUT DATA Assumptions'!G20 -> 19.85 | I25: ='INPUT DATA Assumptions'!H20 -> 19.85 | J25: ='INPUT DATA Assumptions'!I21 -> 25.8 | K25: ='INPUT DATA Assumptions'!J21 -> 25.8 | L25: ='INPUT DATA Assumptions'!K21 -> 25.8 | M25: ='INPUT DATA Assumptions'!L21 -> 25.8 | N25: ='INPUT DATA Assumptions'!M21 -> 25.8
A27: MISC and Other O&M | E27: =E28*E29 -> 11552142 | F27: =F28*F29 -> 10116130 | G27: =G28*G29 -> 10466847 | H27: =H28*H29 -> 10836867 | I27: =I28*I29 -> 11227404 | J27: =J28*J29 -> 13414078 | K27: =K28*K29 -> 13855911 | L27: =L28*L29 -> 14321670 | ... N27: =N28*N29 -> 15331046
B28: Operational Expense | E28: =E10+E15+E19+E23 -> 2.3104284e+08 | F28: =F10+F15+F19+F23 -> 2.023226e+08 | G28: =G10+G15+G19+G23 -> 2.0933695e+08 | H28: =H10+H15+H19+H23 -> 2.1673735e+08 | I28: =I10+I15+I19+I23 -> 2.2454807e+08 | J28: =J10+J15+J19+J23 -> 2.6828157e+08 | K28: =K10+K15+K19+K23 -> 2.7711822e+08 | L28: =L10+L15+L19+L23 -> 2.8643339e+08 | ... N28: =N10+N15+N19+N23 -> 3.0662093e+08
E29: ='INPUT DATA Assumptions'!D22 -> 0.05 | F29: ='INPUT DATA Assumptions'!E22 -> 0.05 | G29: ='INPUT DATA Assumptions'!F22 -> 0.05 | H29: ='INPUT DATA Assumptions'!G22 -> 0.05 | I29: ='INPUT DATA Assumptions'!H22 -> 0.05 | J29: ='INPUT DATA Assumptions'!I22 -> 0.05 | K29: ='INPUT DATA Assumptions'!J22 -> 0.05 | L29: ='INPUT DATA Assumptions'!K22 -> 0.05 | ... N29: ='INPUT DATA Assumptions'!M22 -> 0.05
A31: SERVICE FEE | E31: =E32*E33 -> 24259498 | F31: =F32*F33 -> 21243873 | G31: =G32*G33 -> 21980380 | H31: =H32*H33 -> 22757421 | I31: =I32*I33 -> 23577548 | J31: =J32*J33 -> 28169565 | K31: =K32*K33 -> 29097413 | L31: =L32*L33 -> 30075506 | ... N31: =N32*N33 -> 32195197
B32: Operational Expense | E32: =E10+E15+E19+E23+E27 -> 2.4259498e+08 | F32: =F10+F15+F19+F23+F27 -> 2.1243873e+08 | G32: =G10+G15+G19+G23+G27 -> 2.198038e+08 | H32: =H10+H15+H19+H23+H27 -> 2.2757421e+08 | I32: =I10+I15+I19+I23+I27 -> 2.3577548e+08 | J32: =J10+J15+J19+J23+J27 -> 2.8169565e+08 | K32: =K10+K15+K19+K23+K27 -> 2.9097413e+08 | L32: =L10+L15+L19+L23+L27 -> 3.0075506e+08 | ... N32: =N10+N15+N19+N23+N27 -> 3.2195197e+08
E33: ='INPUT DATA Assumptions'!D23 -> 0.1 | F33: ='INPUT DATA Assumptions'!E23 -> 0.1 | G33: ='INPUT DATA Assumptions'!F23 -> 0.1 | H33: ='INPUT DATA Assumptions'!G23 -> 0.1 | I33: ='INPUT DATA Assumptions'!H23 -> 0.1 | J33: ='INPUT DATA Assumptions'!I23 -> 0.1 | K33: ='INPUT DATA Assumptions'!J23 -> 0.1 | L33: ='INPUT DATA Assumptions'!K23 -> 0.1 | ... N33: ='INPUT DATA Assumptions'!M23 -> 0.1
A35: TOTAL OPEX | E35: =E10+E15+E19+E23+E27+E31 -> 2.6685448e+08 | F35: =F10+F15+F19+F23+F27+F31 -> 2.336826e+08 | G35: =G10+G15+G19+G23+G27+G31 -> 2.4178418e+08 | H35: =H10+H15+H19+H23+H27+H31 -> 2.5033164e+08 | I35: =I10+I15+I19+I23+I27+I31 -> 2.5935302e+08 | J35: =J10+J15+J19+J23+J27+J31 -> 3.0986521e+08 | K35: =K10+K15+K19+K23+K27+K31 -> 3.2007155e+08 | L35: =L10+L15+L19+L23+L27+L31 -> 3.3083057e+08 | ... N35: =N10+N15+N19+N23+N27+N31 -> 3.5414717e+08
A37: 2-MONTHS WORKING CAPITAL | E37: =E35/12*2 -> 44475747 | F37: =F35/12*2 -> 38947100 | G37: =G35/12*2 -> 40297363 | H37: =H35/12*2 -> 41721939 | I37: =I35/12*2 -> 43225504 | J37: =J35/12*2 -> 51644202 | K37: =K35/12*2 -> 53345258 | L37: =L35/12*2 -> 55138428 | ... N37: =N35/12*2 -> 59024528
A39: ANNUAL DEPRECIATION | E39: ='DEPRCTN SCHED'!F35 -> 23169712 | F39: ='DEPRCTN SCHED'!G35 -> 23169712 | G39: ='DEPRCTN SCHED'!H35 -> 23169712 | H39: ='DEPRCTN SCHED'!I35 -> 23169712 | I39: ='DEPRCTN SCHED'!J35 -> 23169712 | J39: ='DEPRCTN SCHED'!K35 -> 27731986 | K39: ='DEPRCTN SCHED'!L35 -> 27731986 | L39: ='DEPRCTN SCHED'!M35 -> 27731986 | ... N39: ='DEPRCTN SCHED'!O35 -> 27731986
A42: AMORTIZATION / INTEREST EXPENSE | E42: ='AMORT SCHED'!C16 -> 0 | F42: ='AMORT SCHED'!D16 -> 0 | G42: ='AMORT SCHED'!E16 -> 0 | H42: ='AMORT SCHED'!F16 -> 0 | I42: ='AMORT SCHED'!G16 -> 0 | J42: ='AMORT SCHED'!H16 -> 0 | K42: ='AMORT SCHED'!I16 -> 0 | L42: ='AMORT SCHED'!J16 -> 0 | ... N42: ='AMORT SCHED'!L16 -> 0
A45: ALLOWABLE RETURN ON INVESTMENT | E45: ='TARIFF CALC'!D18 -> 0 | F45: ='TARIFF CALC'!E18 -> 0 | G45: ='TARIFF CALC'!F18 -> 0 | H45: ='TARIFF CALC'!G18 -> 0 | I45: ='TARIFF CALC'!H18 -> 0 | J45: ='TARIFF CALC'!K18 -> 0 | K45: ='TARIFF CALC'!L18 -> 0 | L45: ='TARIFF CALC'!M18 -> 0 | M45: ='TARIFF CALC'!N18 -> 0 | N45: ='TARIFF CALC'!O18 -> 0
A48: TOTAL ANNUAL REQUIRED REVENUE | E48: =E35+E37+E39+E42+E45 -> 3.3449994e+08 | F48: =F35+F37+F39+F42+F45 -> 2.9579941e+08 | G48: =G35+G37+G39+G42+G45 -> 3.0525125e+08 | H48: =H35+H37+H39+H42+H45 -> 3.1522329e+08 | I48: =I35+I37+I39+I42+I45 -> 3.2574824e+08 | J48: =J35+J37+J39+J42+J45 -> 3.892414e+08 | K48: =K35+K37+K39+K42+K45 -> 4.0114879e+08 | L48: =L35+L37+L39+L42+L45 -> 4.1370098e+08 | ... N48: =N35+N37+N39+N42+N45 -> 4.4090368e+08

Sheet DEPRCTN SCHED
A1: TAGBILARAN WATER WORKS
A2: Economic Life | B2: ='INPUT DATA Assumptions'!B24 -> 25
A4: Annual Depreciation | B4: Construction Period (2026-2029) | F4: Year 1 (2030) | G4: Year 2 | H4: Year 3 | I4: Year 4 | J4: Year 5 | K4: Year 6 | L4: Year 7 | M4: Year 8 | N4: Year 9 | O4: Year 10
A5: 2026 | B5: =B37/B2 -> 6762926.7 | C5: =B5 -> 6762926.7 | D5: =C5 -> 6762926.7 | E5: =D5 -> 6762926.7 | F5: =E5 -> 6762926.7 | G5: =F5 -> 6762926.7 | H5: =G5 -> 6762926.7 | I5: =H5 -> 6762926.7 | J5: =I5 -> 6762926.7 | ... O5: =N5 -> 6762926.7
A6: 2027 | C6: =C37/B2 -> 6518221.8 | D6: =C6 -> 6518221.8 | E6: =D6 -> 6518221.8 | F6: =E6 -> 6518221.8 | G6: =F6 -> 6518221.8 | H6: =G6 -> 6518221.8 | I6: =H6 -> 6518221.8 | J6: =I6 -> 6518221.8 | K6: =J6 -> 6518221.8 | ... O6: =N6 -> 6518221.8
A7: 2028 | D7: =D37/B2 -> 6102714.6 | E7: =D7 -> 6102714.6 | F7: =E7 -> 6102714.6 | G7: =F7 -> 6102714.6 | H7: =G7 -> 6102714.6 | I7: =H7 -> 6102714.6 | J7: =I7 -> 6102714.6 | K7: =J7 -> 6102714.6 | L7: =K7 -> 6102714.6 | ... O7: =N7 -> 6102714.6
A8: 2029 | E8: =E37/B2 -> 3785848.9 | F8: =E8 -> 3785848.9 | G8: =F8 -> 3785848.9 | H8: =G8 -> 3785848.9 | I8: =H8 -> 3785848.9 | J8: =I8 -> 3785848.9 | K8: =J8 -> 3785848.9 | L8: =K8 -> 3785848.9 | M8: =L8 -> 3785848.9 | ... O8: =N8 -> 3785848.9
A9: 2030 | F9: =F37/B2 -> 0 | G9: =F9 -> 0 | H9: =G9 -> 0 | I9: =H9 -> 0 | J9: =I9 -> 0 | K9: =J9 -> 0 | L9: =K9 -> 0 | M9: =L9 -> 0 | N9: =M9 -> 0 | O9: =N9 -> 0
A10: 2031 | G10: =G37/B2 -> 0 | H10: =G10 -> 0 | I10: =H10 -> 0 | J10: =I10 -> 0 | K10: =J10 -> 0 | L10: =K10 -> 0 | M10: =L10 -> 0 | N10: =M10 -> 0 | O10: =N10 -> 0
A11: 2032 | H11: =H37/B2 -> 0 | I11: =H11 -> 0 | J11: =I11 -> 0 | K11: =J11 -> 0 | L11: =K11 -> 0 | M11: =L11 -> 0 | N11: =M11 -> 0 | O11: =N11 -> 0
A12: 2033 | J12: =J37/B2 -> 0 | K12: =J12 -> 0 | L12: =K12 -> 0 | M12: =L12 -> 0 | N12: =M12 -> 0 | O12: =N12 -> 0
A13: 2034 | K13: =K37/B2 -> 4562274.5 | L13: =K13 -> 4562274.5 | M13: =L13 -> 4562274.5 | N13: =M13 -> 4562274.5 | O13: =N13 -> 4562274.5
A14: 2035 | L14: =L37/B2 -> 0 | M14: =L14 -> 0 | N14: =M14 -> 0 | O14: =N14 -> 0
A15: 2036 | M15: =M37/B2 -> 0 | N15: =M15 -> 0 | O15: =N15 -> 0
A16: 2037 | N16: =N37/B2 -> 0 | O16: =N16 -> 0
A17: 2038 | O17: =O37/B2 -> 0
A18: 2039
A19: 2040
A20: 2041
A21: 2042
A22: 2043
A23: 2044
A24: 2045
A25: 2046
A26: 2047
A27: 2048
A28: 2049
A29: 2050
... A34: 2055
A35: Annual Depreciation | B35: =SUM(B5:B34) -> 6762926.7 | C35: =SUM(C5:C34) -> 13281148 | D35: =SUM(D5:D34) -> 19383863 | E35: =SUM(E5:E34) -> 23169712 | F35: =SUM(F5:F34) -> 23169712 | G35: =SUM(G5:G34) -> 23169712 | H35: =SUM(H5:H34) -> 23169712 | I35: =SUM(I5:I34) -> 23169712 | ... O35: =SUM(O5:O34) -> 27731986
A36: Accumulated Depreciation | B36: =B35 -> 6762926.7 | C36: =B36+C35 -> 20044075 | D36: =C36+D35 -> 39427938 | E36: =D36+E35 -> 62597650 | F36: =E36+F35 -> 85767362 | G36: =F36+G35 -> 1.0893707e+08 | H36: =G36+H35 -> 1.3210679e+08 | I36: =H36+I35 -> 1.552765e+08 | J36: =I36+J35 -> 1.7844621e+08 | ... O36: =N36+O35 -> 3.1710614e+08
A37: PPE | B37: ='Tagbilaran CAPEX&OPEX_realistic'!D70 -> 1.6907317e+08 | C37: ='Tagbilaran CAPEX&OPEX_realistic'!E70 -> 1.6295554e+08 | D37: ='Tagbilaran CAPEX&OPEX_realistic'!F70 -> 1.5256786e+08 | E37: ='Tagbilaran CAPEX&OPEX_realistic'!G70 -> 94646223 | F37: ='Tagbilaran CAPEX&OPEX_realistic'!H70 -> 0 | G37: ='Tagbilaran CAPEX&OPEX_realistic'!I70 -> 0 | H37: ='Tagbilaran CAPEX&OPEX_realistic'!J70 -> 0 | I37: ='Tagbilaran CAPEX&OPEX_realistic'!K70 -> 0 | ... O37: ='Tagbilaran CAPEX&OPEX_realistic'!Q70 -> 0
A38: Net Book Value | B38: =B37-B36 -> 1.6231024e+08 | C38: =B37+C37-C36 -> 3.1198464e+08 | D38: =SUM(B37:D37)-D36 -> 4.4516864e+08 | E38: =SUM(B37:E37)-E36 -> 5.1664515e+08 | F38: =SUM(B37:F37)-F36 -> 4.9347544e+08 | G38: =SUM(B37:G37)-G36 -> 4.7030572e+08 | H38: =SUM(B37:H37)-H36 -> 4.4713601e+08 | I38: =SUM(B37:I37)-I36 -> 4.239663e+08 | J38: =SUM(B37:J37)-J36 -> 4.0079659e+08 | K38: =SUM(B37:K37)-K36 -> 4.8712146e+08 | L38: =SUM(B37:L37)-L36 -> 4.5938948e+08 | M38: =SUM(B37:M37)-M36 -> 4.3165749e+08 | N38: =SUM(B37:N37)-N36 -> 4.0392551e+08 | O38: =SUM(B37:O37)-O36 -> 3.7619352e+08

Sheet AMORT SCHED
A1: TAGBILARAN WATER WORKS
B3: CONSTRUCTION PERIOD (2026-2029) | C3: YEAR 1 (2030) | D3: YEAR 2 (2031) | E3: YEAR 3 (2032) | F3: YEAR 4 (2033) | G3: YEAR 5 (2034) | H3: YEAR 6 (2035) | I3: YEAR 7 (2036) | J3: YEAR 8 (2037) | K3: YEAR 9 (2038) | L3: YEAR 10 (2039)
A4: CAPEX | B4: ='INPUT DATA Assumptions'!C10 -> 5.792428e+08 | C4: ='INPUT DATA Assumptions'!D10 -> 0 | D4: ='INPUT DATA Assumptions'!E10 -> 0 | E4: ='INPUT DATA Assumptions'!F10 -> 0 | F4: ='INPUT DATA Assumptions'!G10 -> 0 | G4: ='INPUT DATA Assumptions'!H10 -> 0 | H4: ='INPUT DATA Assumptions'!I10 -> 1.1405686e+08 | I4: ='INPUT DATA Assumptions'!J10 -> 0 | ... L4: ='INPUT DATA Assumptions'!M10 -> 0
A5: Tenor:
A6: Loan | B6: ='INPUT DATA Assumptions'!B40 -> 0 | C6: 0 | D6: 0 | E6: 0 | F6: 0 | G6: 0 | H6: ='INPUT DATA Assumptions'!I40 -> 0 | I6: 0 | J6: 0 | K6: 0 | L6: 0
A7: Grant | B7: ='INPUT DATA Assumptions'!B41 -> 1 | C7: 0 | D7: 0 | E7: 0 | F7: 0 | G7: 0 | H7: ='INPUT DATA Assumptions'!I41 -> 1 | I7: 0 | J7: 0 | K7: 0 | L7: 0
A8: Equity | B8: ='INPUT DATA Assumptions'!B42 -> 0 | C8: 0 | D8: 0 | E8: 0 | F8: 0 | G8: 0 | H8: ='INPUT DATA Assumptions'!I42 -> 0 | I8: 0 | J8: 0 | K8: 0 | L8: ='[45]TARIFF CALC'!P7 -> 0
A9: Interest Rate | B9: ='INPUT DATA Assumptions'!B43 -> 0.05 | C9: 0 | D9: ='[45]TARIFF CALC'!E9 -> 0 | E9: ='[45]TARIFF CALC'!F9 -> 0 | F9: ='[45]TARIFF CALC'!G9 -> 0 | G9: 0 | H9: ='INPUT DATA Assumptions'!I43 -> 0.05 | I9: 0 | J9: ='[45]TARIFF CALC'!N9 -> 0 | K9: 0 | L9: ='[45]TARIFF CALC'!P9 -> 0
A10: Repayment Period | B10: ='INPUT DATA Assumptions'!B44 -> 30 | C10: ='[45]TARIFF CALC'!D10 -> 0 | D10: ='[45]TARIFF CALC'!E10 -> 0 | E10: ='[45]TARIFF CALC'!F10 -> 0 | F10: ='[45]TARIFF CALC'!G10 -> 0 | G10: ='[45]TARIFF CALC'!H10 -> 0 | H10: ='INPUT DATA Assumptions'!I44 -> 30 | I10: 0 | J10: ='[45]TARIFF CALC'!N10 -> 0 | K10: ='[45]TARIFF CALC'!O10 -> 0 | L10: ='[45]TARIFF CALC'!P10 -> 0
A13: Loan 1 (Year2) | B13: CONSTRUCTION PERIOD (2026-2029) | C13: YEAR 1 (2030) | D13: YEAR 2 (2031) | E13: YEAR 3 (2032) | F13: YEAR 4 (2033) | G13: YEAR 5 (2034) | H13: YEAR 6 (2035) | I13: YEAR 7 (2036) | J13: YEAR 8 (2037) | K13: YEAR 9 (2038) | L13: YEAR 10 (2039)
A14: Loan | B14: =B4*B6 -> 0 | C14: =C4*C6 -> 0 | D14: =D4*D6 -> 0 | E14: 0 | F14: 0 | H14: =H4*H6 -> 0
A15: TOTAL Loan | B15: =B14 -> 0 | C15: =B15+C14 -> 0 | D15: =C15+D14 -> 0 | E15: 0 | F15: =E15+F14 -> 0 | H15: =H14 -> 0
A16: Interest Expense | B16: =B15*B9 -> 0 | C16: =B19*B9 -> 0 | D16: =C19*B9 -> 0 | E16: =D19*B9 -> 0 | F16: =E19*B9 -> 0 | G16: =F19*B9 -> 0 | H16: =H15*H9 -> 0 | I16: =H19*H9 -> 0 | J16: =I19*H9 -> 0 | K16: =J19*H9 -> 0 | L16: =K19*H9 -> 0
A17: Principal Repayment | B17: =B18-B16 -> 0 | C17: =C18-C16 -> 0 | D17: =D18-D16 -> 0 | E17: =E18-E16 -> 0 | F17: =F18-F16 -> 0 | G17: =G18-G16 -> 0 | H17: =H18-H16 -> 0 | I17: =I18-I16 -> 0 | ... L17: =L18-L16 -> 0
A18: Debt Service | B18: =-PMT(B9,B10,B15) -> 0 | C18: =B18 -> 0 | D18: =C18 -> 0 | E18: =D18 -> 0 | F18: =E18 -> 0 | G18: =F18 -> 0 | H18: =-PMT(H9,H10,H15) -> 0 | I18: =H18 -> 0 | J18: =I18 -> 0 | K18: =J18 -> 0 | L18: =K18 -> 0
A19: Outstanding Loan | B19: =B15-B17 -> 0 | C19: =B19-C17 -> 0 | D19: =D15-D17 -> 0 | E19: =D19-E17 -> 0 | F19: =E19-F17 -> 0 | G19: =F19-G17 -> 0 | H19: =H15-H17 -> 0 | I19: =H19-I17 -> 0 | J19: =I19-J17 -> 0 | K19: =J19-K17 -> 0 | L19: =K19-L17 -> 0

Sheet TARIFF CALC
A1: TAGBILARAN WATERWORKS
B2: 1st Regulatory Period (1RP)
A3: ASSUMPTIONS | C3: CONSTRUCTION PERIOD (2026-2029) | D3: YEAR 1 (2030) | E3: YEAR 2 (2031) | F3: YEAR 3 (2032) | G3: YEAR 4 (2033) | H3: YEAR 5 (2034) | K3: YEAR 6 (2035) | L3: YEAR 7 (2036) | M3: YEAR 8 (2037) | N3: YEAR 9 (2038) | O3: YEAR 10 (2039)
A5: Property and Equipment, Beg, | C5: =C6 -> 5.792428e+08 | D5: =C6+D6 -> 5.792428e+08 | E5: =D5+E6 -> 5.792428e+08 | F5: =E5+F6 -> 5.792428e+08 | G5: =F5+G6 -> 5.792428e+08 | H5: =G5+H6 -> 5.792428e+08 | K5: =H5+K6 -> 6.9329966e+08 | L5: =K5+L6 -> 6.9329966e+08 | M5: =L5+M6 -> 6.9329966e+08 | N5: =M5+N6 -> 6.9329966e+08 | O5: =N5+O6 -> 6.9329966e+08
A6: New Investment | C6: ='INPUT DATA Assumptions'!C10 -> 5.792428e+08 | D6: ='INPUT DATA Assumptions'!D10 -> 0 | E6: ='INPUT DATA Assumptions'!E10 -> 0 | F6: ='INPUT DATA Assumptions'!F10 -> 0 | G6: ='INPUT DATA Assumptions'!G10 -> 0 | H6: ='INPUT DATA Assumptions'!H10 -> 0 | K6: ='INPUT DATA Assumptions'!I10 -> 1.1405686e+08 | L6: ='INPUT DATA Assumptions'!J10 -> 0 | M6: ='INPUT DATA Assumptions'!K10 -> 0 | N6: ='INPUT DATA Assumptions'!L10 -> 0 | O6: ='INPUT DATA Assumptions'!M10 -> 0
A7: Annual Acc Depreciation | C7: ='DEPRCTN SCHED'!E36 -> 62597650 | D7: ='DEPRCTN SCHED'!F36 -> 85767362 | E7: ='DEPRCTN SCHED'!G36 -> 1.0893707e+08 | F7: ='DEPRCTN SCHED'!H36 -> 1.3210679e+08 | G7: ='DEPRCTN SCHED'!I36 -> 1.552765e+08 | H7: ='DEPRCTN SCHED'!J36 -> 1.7844621e+08 | K7: ='DEPRCTN SCHED'!K36 -> 2.061782e+08 | L7: ='DEPRCTN SCHED'!L36 -> 2.3391018e+08 | M7: ='DEPRCTN SCHED'!M36 -> 2.6164217e+08 | N7: ='DEPRCTN SCHED'!N36 -> 2.8937416e+08 | O7: ='DEPRCTN SCHED'!O36 -> 3.1710614e+08
A8: NET BOOK VALUE | C8: =C5-C7 -> 5.1664515e+08 | D8: =D5-D7 -> 4.9347544e+08 | E8: =E5-E7 -> 4.7030572e+08 | F8: =F5-F7 -> 4.4713601e+08 | G8: =G5-G7 -> 4.239663e+08 | H8: =H5-H7 -> 4.0079659e+08 | K8: =K5-K7 -> 4.8712146e+08 | L8: =L5-L7 -> 4.5938948e+08 | M8: =M5-M7 -> 4.3165749e+08 | N8: =N5-N7 -> 4.0392551e+08 | O8: =O5-O7 -> 3.7619352e+08
A10: ADD: Working Capital
A11: OPEX | D11: =OPEX!E35 -> 2.6685448e+08 | E11: =OPEX!F35 -> 2.336826e+08 | F11: =OPEX!G35 -> 2.4178418e+08 | G11: =OPEX!H35 -> 2.5033164e+08 | H11: =OPEX!I35 -> 2.5935302e+08 | K11: =OPEX!J35 -> 3.0986521e+08 | L11: =OPEX!K35 -> 3.2007155e+08 | M11: =OPEX!L35 -> 3.3083057e+08 | N11: =OPEX!M35 -> 3.4217682e+08 | O11: =OPEX!N35 -> 3.5414717e+08
A12: AMORTIZATION (Interest Expense) | D12: =OPEX!E42 -> 0 | E12: =OPEX!F42 -> 0 | F12: =OPEX!G42 -> 0 | G12: =OPEX!H42 -> 0 | H12: =OPEX!I42 -> 0 | K12: =OPEX!J42 -> 0 | L12: =OPEX!K42 -> 0 | M12: =OPEX!L42 -> 0 | N12: =OPEX!M42 -> 0 | O12: =OPEX!N42 -> 0
A13: DEPRECIATION | D13: =OPEX!E39 -> 23169712 | E13: =OPEX!F39 -> 23169712 | F13: =OPEX!G39 -> 23169712 | G13: =OPEX!H39 -> 23169712 | H13: =OPEX!I39 -> 23169712 | K13: =OPEX!J39 -> 27731986 | L13: =OPEX!K39 -> 27731986 | M13: =OPEX!L39 -> 27731986 | N13: =OPEX!M39 -> 27731986 | O13: =OPEX!N39 -> 27731986
A14: 2-months WORKING CAPITAL | D14: =OPEX!E37 -> 44475747 | E14: =OPEX!F37 -> 38947100 | F14: =OPEX!G37 -> 40297363 | G14: =OPEX!H37 -> 41721939 | H14: =OPEX!I37 -> 43225504 | K14: =OPEX!J37 -> 51644202 | L14: =OPEX!K37 -> 53345258 | M14: =OPEX!L37 -> 55138428 | N14: =OPEX!M37 -> 57029471 | O14: =OPEX!N37 -> 59024528
A15: EQUITY | D15: ='INPUT DATA Assumptions'!C39*'INPUT DATA Assumptions'!B42 -> 0 | E15: ='INPUT DATA Assumptions'!D39*'INPUT DATA Assumptions'!C42 -> 0 | F15: ='INPUT DATA Assumptions'!E39*'INPUT DATA Assumptions'!D42 -> 0 | G15: ='INPUT DATA Assumptions'!F39*'INPUT DATA Assumptions'!E42 -> 0 | H15: ='INPUT DATA Assumptions'!G39*'INPUT DATA Assumptions'!F42 -> 0 | K15: ='INPUT DATA Assumptions'!I39*'INPUT DATA Assumptions'!I42 -> 0 | L15: =K15 -> 0 | M15: =L15 -> 0 | N15: =M15 -> 0 | O15: =N15 -> 0
A16: TOTAL ANNUAL REQUIRED REVENUE | C16: 0 | D16: =SUM(D11:D15) -> 3.3449994e+08 | E16: =SUM(E11:E15) -> 2.9579941e+08 | F16: =SUM(F11:F15) -> 3.0525125e+08 | G16: =SUM(G11:G15) -> 3.1522329e+08 | H16: =SUM(H11:H15) -> 3.2574824e+08 | K16: =SUM(K11:K15) -> 3.892414e+08 | L16: =SUM(L11:L15) -> 4.0114879e+08 | M16: =SUM(M11:M15) -> 4.1370098e+08 | N16: =SUM(N11:N15) -> 4.2693828e+08 | O16: =SUM(O11:O15) -> 4.4090368e+08
A18: MAXIMUN ALLOWABLE ROI | C18: 0 | D18: =D8*'INPUT DATA Assumptions'!$B$47 -> 0 | E18: =E8*'INPUT DATA Assumptions'!$B$47 -> 0 | F18: =F8*'INPUT DATA Assumptions'!$B$47 -> 0 | G18: =G8*'INPUT DATA Assumptions'!$B$47 -> 0 | H18: =H8*'INPUT DATA Assumptions'!$B$47 -> 0 | K18: =K8*'INPUT DATA Assumptions'!$I$47 -> 0 | L18: =L8*'INPUT DATA Assumptions'!$I$47 -> 0 | M18: =M8*'INPUT DATA Assumptions'!$I$47 -> 0 | N18: =N8*'INPUT DATA Assumptions'!$I$47 -> 0 | O18: =O8*'INPUT DATA Assumptions'!$I$47 -> 0
A19: MAXIMUM ALLOWABLE REVENUE | C19: =C16+C18 -> 0 | D19: =D16+D18 -> 3.3449994e+08 | E19: =E16+E18 -> 2.9579941e+08 | F19: =F16+F18 -> 3.0525125e+08 | G19: =G16+G18 -> 3.1522329e+08 | H19: =H16+H18 -> 3.2574824e+08 | K19: =K16+K18 -> 3.892414e+08 | L19: =L16+L18 -> 4.0114879e+08 | M19: =M16+M18 -> 4.1370098e+08 | N19: =N16+N18 -> 4.2693828e+08 | O19: =O16+O18 -> 4.4090368e+08
A21: VOLUME SOLD M3 | D21: ='INPUT DATA Assumptions'!D5+'INPUT DATA Assumptions'!D6+'INPUT DATA Assumptions'!D7 -> 15247188 | E21: ='INPUT DATA Assumptions'!E5+'INPUT DATA Assumptions'!E6+'INPUT DATA Assumptions'!E7 -> 14306028 | F21: ='INPUT DATA Assumptions'!F5+'INPUT DATA Assumptions'!F6+'INPUT DATA Assumptions'!F7 -> 14495454 | G21: ='INPUT DATA Assumptions'!G5+'INPUT DATA Assumptions'!G6+'INPUT DATA Assumptions'!G7 -> 14689219 | H21: ='INPUT DATA Assumptions'!H5+'INPUT DATA Assumptions'!H6+'INPUT DATA Assumptions'!H7 -> 14887516 | K21: ='INPUT DATA Assumptions'!I5+'INPUT DATA Assumptions'!I6+'INPUT DATA Assumptions'!I7 -> 15089949 | L21: ='INPUT DATA Assumptions'!J5+'INPUT DATA Assumptions'!J6+'INPUT DATA Assumptions'!J7 -> 15281363 | M21: ='INPUT DATA Assumptions'!K5+'INPUT DATA Assumptions'!K6+'INPUT DATA Assumptions'!K7 -> 15477487 | N21: ='INPUT DATA Assumptions'!L5+'INPUT DATA Assumptions'!L6+'INPUT DATA Assumptions'!L7 -> 15678563 | O21: ='INPUT DATA Assumptions'!M5+'INPUT DATA Assumptions'!M6+'INPUT DATA Assumptions'!M7 -> 15884849
A22: REQUIRED TARIFF (Php/m3) | D22: =D19/D21 -> 21.938468 | E22: =E19/E21 -> 20.676557 | F22: =F19/F21 -> 21.058413 | G22: =G19/G21 -> 21.459499 | H22: =H19/H21 -> 21.880631 | K22: =K19/K21 -> 25.794746 | L22: =L19/L21 -> 26.250851 | M22: =M19/M21 -> 26.729209 | N22: =N19/N21 -> 27.230702 | O22: =O19/O21 -> 27.756239
D25: PROPOSED TARIFF | K25: PROPOSED TARIFF
A26: Proposed Tariff | D26: YEAR1 | E26: YEAR2 | F26: YEAR3 | G26: YEAR4 | H26: YEAR5 | I26: AVERAGE | K26: YEAR1 | L26: YEAR2 | M26: YEAR3 | N26: YEAR4 | O26: YEAR5 | P26: AVERAGE
A28: Minimuim Charge 0-10m3 | D28: =D19/D21 -> 21.938468 | E28: =E19/E21 -> 20.676557 | F28: =F19/F21 -> 21.058413 | G28: =G19/G21 -> 21.459499 | H28: =H19/H21 -> 21.880631 | I28: =SUM(D28:H28)/5*10 -> 214.02714 | K28: =K19/K21 -> 25.794746 | L28: =L19/L21 -> 26.250851 | M28: =M19/M21 -> 26.729209 | N28: =N19/N21 -> 27.230702 | O28: =O19/O21 -> 27.756239 | P28: =SUM(K28:O28)/5*10 -> 267.5235
A29: Commodity Charge 11-20 per m3 | D29: =D28*(1+$D$34) -> 23.035391 | E29: =E28*(1+$D$34) -> 21.710385 | F29: =F28*(1+$D$34) -> 22.111334 | G29: =G28*(1+$D$34) -> 22.532474 | H29: =H28*(1+$D$34) -> 22.974663 | I29: =SUM(D29:H29)/5 -> 22.472849 | K29: =K28*(1+$K$34) -> 27.084483 | L29: =L28*(1+$K$34) -> 27.563394 | M29: =M28*(1+$K$34) -> 28.065669 | N29: =N28*(1+$K$34) -> 28.592238 | O29: =O28*(1+$K$34) -> 29.144051 | P29: =SUM(K29:O29)/5 -> 28.089967
A30: 21-30 per m3 | D30: =D29*(1+$D$34) -> 24.187161 | E30: =E29*(1+$D$34) -> 22.795904 | F30: =F29*(1+$D$34) -> 23.2169 | G30: =G29*(1+$D$34) -> 23.659098 | H30: =H29*(1+$D$34) -> 24.123396 | I30: =SUM(D30:H30)/5 -> 23.596492 | K30: =K29*(1+$K$34) -> 28.438707 | L30: =L29*(1+$K$34) -> 28.941564 | M30: =M29*(1+$K$34) -> 29.468952 | N30: =N29*(1+$K$34) -> 30.021849 | O30: =O29*(1+$K$34) -> 30.601254 | P30: =SUM(K30:O30)/5 -> 29.494465
A31: 31-40 per m3 | D31: =D30*(1+$D$34) -> 25.396519 | E31: =E30*(1+$D$34) -> 23.935699 | F31: =F30*(1+$D$34) -> 24.377745 | G31: =G30*(1+$D$34) -> 24.842053 | H31: =H30*(1+$D$34) -> 25.329566 | I31: =SUM(D31:H31)/5 -> 24.776316 | K31: =K30*(1+$K$34) -> 29.860642 | L31: =L30*(1+$K$34) -> 30.388642 | M31: =M30*(1+$K$34) -> 30.9424 | N31: =N30*(1+$K$34) -> 31.522942 | O31: =O30*(1+$K$34) -> 32.131317 | P31: =SUM(K31:O31)/5 -> 30.969189
A32: 41-50 per m3 | D32: =D31*(1+$D$34) -> 26.666345 | E32: =E31*(1+$D$34) -> 25.132484 | F32: =F31*(1+$D$34) -> 25.596633 | G32: =G31*(1+$D$34) -> 26.084155 | H32: =H31*(1+$D$34) -> 26.596044 | I32: =SUM(D32:H32)/5 -> 26.015132 | K32: =K31*(1+$K$34) -> 31.353675 | L32: =L31*(1+$K$34) -> 31.908074 | M32: =M31*(1+$K$34) -> 32.48952 | N32: =N31*(1+$K$34) -> 33.099089 | O32: =O31*(1+$K$34) -> 33.737883 | P32: =SUM(K32:O32)/5 -> 32.517648
A33: 51-up per m3 | D33: =D32*(1+$D$34) -> 27.999662 | E33: =E32*(1+$D$34) -> 26.389108 | F33: =F32*(1+$D$34) -> 26.876464 | G33: =G32*(1+$D$34) -> 27.388363 | H33: =H32*(1+$D$34) -> 27.925846 | I33: =SUM(D33:H33)/5 -> 27.315889 | K33: =K32*(1+$K$34) -> 32.921358 | L33: =L32*(1+$K$34) -> 33.503478 | M33: =M32*(1+$K$34) -> 34.113996 | N33: =N32*(1+$K$34) -> 34.754044 | O33: =O32*(1+$K$34) -> 35.424777 | P33: =SUM(K33:O33)/5 -> 34.14353
